<robot name="abhiyan">
  <link name="bot_base" />
  <link name="lidar" />
  <link name="camera_base" />
  <link name="camera" />
  <link name="odom"  />

  <joint name="bot_base_lidar" type="continuous">
    <parent link="bot_base"/>
    <child link="lidar"/>
    <origin xyz="0.30 0 0" rpy="0 0 0" />
    <axis xyz="0 0 0" /> 
 </joint>

  <joint name="odometry" type="continuous">
    <parent link="bot_base"/>
    <child link="odometry"/>
    <origin xyz="0 0 0" rpy="0 0 0" />
    <axis xyz="0 0 0" /> 
 </joint>

  <joint name="bot_base_camera_base" type="continuous">
    <parent link="bot_base"/>
    <child link="camera_base"/>
    <origin xyz="0 1.5 0" rpy="0 0 0" />
    <axis xyz="0 0 0" />
 </joint>

  <joint name="camera" type="continuous">
    <parent link="camera_base"/>
    <child link="camera"/>
    <origin xyz="0.707 -0.707 0" rpy="0 0 0" />
  </joint>
</robot>
